<?xml version="1.0" encoding="utf-8"?>
<robot>
  <link name="base_link">
 <visual>
    <geometry>
    <box size="0.4 0.3 0.1" />
    </geometry>
    <material name="green">
    <color rgba="0 1 0 1" />
    </material>
</visual>
<collision name="base_link_collision">
    <geometry>
    <box size="0.4 0.3 0.1" />
    </geometry>
</collision>
</link>

  <link name="link1">
    <inertial>
      <origin xyz="0.0 0.0 -0.5" rpy="0.0 0.0 0.0"/>
      <mass value="1.0"/>
      <inertia ixx="-0.25" ixy="0.0" ixz="0.0" iyy="0.08300000000000002" iyz="0.0" izz="0.0"/>
    </inertial><visual>
<origin xyz="0 0 -0.5" rpy="0 0 0" />
<geometry>
    <cylinder length="1.0" radius="0.05" />
</geometry>
<material name="red">
    <color rgba="1 0 0 1" />
</material>
</visual>
<collision name="link1_collision">
<origin xyz="0 0 -0.5" rpy="0 0 0" />
<geometry>
    <cylinder length="1.0" radius="0.05" />
</geometry>
</collision>

  </link>
  <link name="link2">
    <inertial>
      <origin xyz="0.0 0.0 -1.0" rpy="0.0 0.0 0.0"/>
      <mass value="1.0"/>
      <inertia ixx="-1.0" ixy="0.0" ixz="0.0" iyy="0.33000000000000007" iyz="0.0" izz="0.0"/>
    </inertial><visual>
<origin xyz="0 0 -1.0" rpy="0 0 0" />
<geometry>
    <cylinder length="2.0" radius="0.05" />
</geometry>
<material name="blue">
    <color rgba="0 0 1 1" />
</material>
</visual>
<collision name="link2_collision">
<origin xyz="0 0 -1.0" rpy="0 0 0" />
<geometry>
    <cylinder length="2.0" radius="0.05" />
</geometry>
</collision>

  </link>
  <joint name="joint1" type="continuous">
    <parent link="base_link"/>
    <child link="link1"/>
    <origin xyz="0.0 0.0 0.0" rpy="0.0 -0.0 0.0"/>
    <axis xyz="0.0 1.0 0.0"/>
    <limit effort="Inf" velocity="Inf"/>
  </joint>
  <joint name="joint2" type="continuous">
    <parent link="link1"/>
    <child link="link2"/>
    <origin xyz="0.0 0.0 -1.0" rpy="0.0 -0.0 0.0"/>
    <axis xyz="0.0 1.0 0.0"/>
    <limit effort="Inf" velocity="Inf"/>
  </joint>
</robot>
